<?xml version="1.0"?>
<robot xmlns:xacro="http://www.ros.org/wiki/xacro">
    
    <xacro:include filename="colors.xacro" />
    <xacro:include filename="inertial.xacro" />

    <link name="base_link">
    </link>
    
    <xacro:property name="chassis_joint_x" value="-0.1"/>
    <xacro:property name="chassis_joint_y" value="0"/>
    <xacro:property name="chassis_joint_z" value="0"/>

    <joint name="chassis_joint" type="fixed">
        <parent link="base_link"/>
        <child link="chassis"/>
        <origin xyz="${chassis_joint_x} ${chassis_joint_y} ${chassis_joint_z}"/>
    </joint>

    <xacro:property name="chassis_x" value="0.15"/>
    <xacro:property name="chassis_y" value="0"/>
    <xacro:property name="chassis_z" value="0.075"/>

    <xacro:property name="chassis_w" value="0.3"/>
    <xacro:property name="chassis_l" value="0.3"/>
    <xacro:property name="chassis_h" value="0.15"/>

    <xacro:property name="chassis_roll" value="0"/>
    <xacro:property name="chassis_pitch" value="0"/>
    <xacro:property name="chassis_yaw" value="0"/>

    <xacro:property name="chassis_m" value="0.5"/>

    <link name="chassis">
        <visual>
            <origin xyz="${chassis_x} ${chassis_y} ${chassis_z}"/>
            <geometry>
                <box size="${chassis_w} ${chassis_l} ${chassis_h}"/>
            </geometry>
            <material name="green"/>
        </visual>
        <collision>
            <origin xyz="${chassis_x} ${chassis_y} ${chassis_z}" rpy="${chassis_roll} ${chassis_pitch} ${chassis_yaw}"/>
            <geometry>
                <box size="${chassis_w} ${chassis_l} ${chassis_h}"/>
            </geometry>
        </collision>
        <xacro:inertial_box mass="${chassis_m}" x="${chassis_w}" y="${chassis_l}" z="${chassis_h}">
            <origin xyz="${chassis_x} ${chassis_y} ${chassis_z}" rpy="${chassis_roll} ${chassis_pitch} ${chassis_yaw}"/>
        </xacro:inertial_box>    
    </link>
    
    <!-- LEFT WHEEL -->

    <xacro:property name="l_wheel_joint_x" value="0"/>
    <xacro:property name="l_wheel_joint_y" value="0.175"/>
    <xacro:property name="l_wheel_joint_z" value="0"/>

    <xacro:property name="l_wheel_joint_ax" value="0"/>
    <xacro:property name="l_wheel_joint_ay" value="0"/>
    <xacro:property name="l_wheel_joint_az" value="1"/>

    <xacro:property name="l_wheel_joint_roll" value="-${pi/2}"/>
    <xacro:property name="l_wheel_joint_pitch" value="0"/>
    <xacro:property name="l_wheel_joint_yaw" value="0"/>

    <joint name="left_wheel_joint" type="continuous">
        <parent link="base_link"/>
        <child link="left_wheel"/>
        <origin xyz="${l_wheel_joint_x} ${l_wheel_joint_y} ${l_wheel_joint_z}" rpy="${l_wheel_joint_roll} ${l_wheel_joint_pitch} ${l_wheel_joint_yaw}" />
        <axis xyz="${l_wheel_joint_ax} ${l_wheel_joint_ay} ${l_wheel_joint_az}"/>
    </joint>

    <xacro:property name="l_wheel_length" value="0.04"/>
    <xacro:property name="l_wheel_radius" value="0.05"/>
    <xacro:property name="l_wheel_m" value="0.1"/>

    <xacro:property name="l_wheel_x" value="0"/>
    <xacro:property name="l_wheel_y" value="0"/>
    <xacro:property name="l_wheel_z" value="0"/>

    <xacro:property name="l_wheel_roll" value="0"/>
    <xacro:property name="l_wheel_pitch" value="0"/>
    <xacro:property name="l_wheel_yaw" value="0"/>

    <link name="left_wheel">
        <visual>
            <geometry>
                <cylinder length="${l_wheel_length}" radius="${l_wheel_radius}"/>
            </geometry>
            <material name="blue"/>
        </visual>    
        <collision>
            <geometry>
                <cylinder length="${l_wheel_length}" radius="${l_wheel_radius}"/>
            </geometry>
        </collision>
        <xacro:inertial_cylinder mass="${l_wheel_m}" length="${l_wheel_length}" radius="${l_wheel_radius}">
            <origin xyz="${l_wheel_x} ${l_wheel_y} ${l_wheel_z}" rpy="${l_wheel_roll} ${l_wheel_pitch} ${l_wheel_yaw}"/>
        </xacro:inertial_cylinder>
    </link>

    <!-- RIGHT WHEEL -->

    <xacro:property name="r_wheel_joint_x" value="0"/>
    <xacro:property name="r_wheel_joint_y" value="-0.175"/>
    <xacro:property name="r_wheel_joint_z" value="0"/>

    <xacro:property name="r_wheel_joint_ax" value="0"/>
    <xacro:property name="r_wheel_joint_ay" value="0"/>
    <xacro:property name="r_wheel_joint_az" value="-1"/>

    <xacro:property name="r_wheel_joint_roll" value="${pi/2}"/>
    <xacro:property name="r_wheel_joint_pitch" value="0"/>
    <xacro:property name="r_wheel_joint_yaw" value="0"/>

    <joint name="right_wheel_joint" type="continuous">
        <parent link="base_link"/>
        <child link="right_wheel"/>
        <origin xyz="${r_wheel_joint_x} ${r_wheel_joint_y} ${r_wheel_joint_z}" rpy="${r_wheel_joint_roll} ${r_wheel_joint_pitch} ${r_wheel_joint_yaw}" />
        <axis xyz="${r_wheel_joint_ax} ${r_wheel_joint_ay} ${r_wheel_joint_az}"/>
    </joint>

    <xacro:property name="r_wheel_length" value="0.04"/>
    <xacro:property name="r_wheel_radius" value="0.05"/>
    <xacro:property name="r_wheel_m" value="0.1"/>

    <xacro:property name="r_wheel_x" value="0"/>
    <xacro:property name="r_wheel_y" value="0"/>
    <xacro:property name="r_wheel_z" value="0"/>

    <xacro:property name="r_wheel_roll" value="0"/>
    <xacro:property name="r_wheel_pitch" value="0"/>
    <xacro:property name="r_wheel_yaw" value="0"/>

    <link name="right_wheel">
        <visual>
            <geometry>
                <cylinder length="${r_wheel_length}" radius="${r_wheel_radius}"/>
            </geometry>
            <material name="blue"/>
        </visual>    
        <collision>
            <geometry>
                <cylinder length="${r_wheel_length}" radius="${r_wheel_radius}"/>
            </geometry>
        </collision>
        <xacro:inertial_cylinder mass="${r_wheel_m}" length="${r_wheel_length}" radius="${r_wheel_radius}">
            <origin xyz="${r_wheel_x} ${r_wheel_y} ${r_wheel_z}" rpy="${r_wheel_roll} ${r_wheel_pitch} ${r_wheel_yaw}"/>
        </xacro:inertial_cylinder>
    </link>

    <xacro:property name="c_wheel_joint_x" value="0.24"/>
    <xacro:property name="c_wheel_joint_y" value="0"/>
    <xacro:property name="c_wheel_joint_z" value="0"/>

    <xacro:property name="c_wheel_joint_roll" value="0"/>
    <xacro:property name="c_wheel_joint_pitch" value="0"/>
    <xacro:property name="c_wheel_joint_yaw" value="0"/>

    <!-- CASTER WHEEL -->
    <joint name="caster_wheel_joint" type="fixed">
        <parent link="chassis"/>
        <child link="caster_wheel"/>
        <origin xyz="${c_wheel_joint_x} ${c_wheel_joint_y} ${c_wheel_joint_z}" rpy="${c_wheel_joint_roll} ${c_wheel_joint_pitch} ${c_wheel_joint_yaw}"/>
    </joint>

    <xacro:property name="c_wheel_radius" value="0.05"/>
    <xacro:property name="c_wheel_mass" value="0.1"/>
    <xacro:property name="c_wheel_x" value="0"/>
    <xacro:property name="c_wheel_y" value="0"/>
    <xacro:property name="c_wheel_z" value="0"/>
    <xacro:property name="c_wheel_roll" value="0"/>
    <xacro:property name="c_wheel_pitch" value="0"/>
    <xacro:property name="c_wheel_yaw" value="0"/>

    <link name="caster_wheel">
        <visual>
            <geometry>
                <sphere radius="${c_wheel_radius}"/>
            </geometry>
            <material name="black"/>
        </visual>
        <collision>
            <geometry>
                <sphere radius="${c_wheel_radius}"/>
            </geometry>
        </collision>
        <xacro:inertial_sphere mass="${c_wheel_mass}" radius="${c_wheel_radius}">
            <origin xyz="${c_wheel_x} ${c_wheel_y} ${c_wheel_z}" rpy="${c_wheel_roll} ${c_wheel_pitch} ${c_wheel_yaw}"/>
        </xacro:inertial_sphere>
    </link>
    
    
</robot>