<?xml version="1.0" ?>
<!-- =================================================================================== -->
<!-- |    This document was autogenerated by xacro from robot.urdf.xacro               | -->
<!-- |    EDITING THIS FILE BY HAND IS NOT RECOMMENDED                                 | -->
<!-- =================================================================================== -->
<robot name="robot">
  <!-- Specify some standard inertial calculations 
         https://en.wikipedia.org/wiki/List_of_moments_of_inertia
         These make use of xacro's mathematical functionality -->
  <gazebo>
    <pose>0 0 0.05 0 0 0</pose>
  </gazebo>
  <gazebo>
    <plugin filename="libignition-gazebo-diff-drive-system.so" name="ignition::gazebo::systems::DiffDrive">
      <left_joint>left_wheel_joint</left_joint>
      <right_joint>right_wheel_joint</right_joint>
      <wheel_separation>0.3</wheel_separation>
      <wheel_radius>0.05</wheel_radius>
      <odom_publish_frequency>1</odom_publish_frequency>
      <topic>cmd_vel</topic>
    </plugin>
  </gazebo>
  <gazebo reference="caster_wheel">
    <mu1 value="0.0"/>
    <mu2 value="0.0"/>
  </gazebo>
  <gazebo>
    <plugin filename="libignition-gazebo-joint-state-publisher-system" name="ignition::gazebo::systems::JointStatePublisher">
        </plugin>
    <plugin filename="libignition-gazebo-odometry-publisher-system" name="ignition::gazebo::systems::OdometryPublisher">
      <odom_frame>world</odom_frame>
      <robot_base_frame>base_link</robot_base_frame>
    </plugin>
  </gazebo>
  <material name="white">
    <color rgba="1 1 1 1"/>
  </material>
  <material name="orange">
    <color rgba="1 0.3 0.1 1"/>
  </material>
  <material name="green">
    <color rgba="0 1 0 1"/>
  </material>
  <material name="blue">
    <color rgba="0 0 1 1"/>
  </material>
  <material name="black">
    <color rgba="0 0 0 1"/>
  </material>
  <material name="magenta">
    <color rgba="1 0 1 1"/>
  </material>
  <material name="red">
    <color rgba="1 0 0 1"/>
  </material>
  <!-- Specify some standard inertial calculations 
         https://en.wikipedia.org/wiki/List_of_moments_of_inertia
         These make use of xacro's mathematical functionality -->
  <link name="base_link">
    </link>
  <joint name="chassis_joint" type="fixed">
    <parent link="base_link"/>
    <child link="chassis"/>
    <origin xyz="0 0 0"/>
  </joint>
  <link name="chassis">
    <visual>
      <origin xyz="0 0 0.2"/>
      <geometry>
        <box size="1.0 0.4 0.2"/>
      </geometry>
      <material name="blue"/>
    </visual>
    <collision>
      <origin rpy="0 0 0" xyz="0 0 0.2"/>
      <geometry>
        <box size="1.0 0.4 0.2"/>
      </geometry>
    </collision>
    <inertial>
      <origin rpy="0 0 0" xyz="0 0 0.2"/>
      <mass value="0.5"/>
      <inertia ixx="0.008333333333333335" ixy="0.0" ixz="0.0" iyy="0.043333333333333335" iyz="0.0" izz="0.04833333333333334"/>
    </inertial>
  </link>
  <!-- LEFT WHEEL -->
  <joint name="left_wheel_joint" type="continuous">
    <parent link="base_link"/>
    <child link="left_wheel"/>
    <origin rpy="-1.5707963267948966 0 0" xyz="0.3 0.25 0.2"/>
    <axis xyz="0 0 1"/>
  </joint>
  <link name="left_wheel">
    <visual>
      <geometry>
        <cylinder length="0.1" radius="0.2"/>
      </geometry>
      <material name="red"/>
    </visual>
    <collision>
      <geometry>
        <cylinder length="0.1" radius="0.2"/>
      </geometry>
    </collision>
    <inertial>
      <origin rpy="0 0 0" xyz="0 0 0"/>
      <mass value="0.1"/>
      <inertia ixx="0.0010833333333333335" ixy="0.0" ixz="0.0" iyy="0.0010833333333333335" iyz="0.0" izz="0.0020000000000000005"/>
    </inertial>
  </link>
  <!-- RIGHT WHEEL -->
  <joint name="right_wheel_joint" type="continuous">
    <parent link="base_link"/>
    <child link="right_wheel"/>
    <origin rpy="1.5707963267948966 0 0" xyz="0.3 -0.25 0.2"/>
    <axis xyz="0 0 -1"/>
  </joint>
  <link name="right_wheel">
    <visual>
      <geometry>
        <cylinder length="0.1" radius="0.2"/>
      </geometry>
      <material name="red"/>
    </visual>
    <collision>
      <geometry>
        <cylinder length="0.1" radius="0.2"/>
      </geometry>
    </collision>
    <inertial>
      <origin rpy="0 0 0" xyz="0 0 0"/>
      <mass value="0.1"/>
      <inertia ixx="0.0010833333333333335" ixy="0.0" ixz="0.0" iyy="0.0010833333333333335" iyz="0.0" izz="0.0020000000000000005"/>
    </inertial>
  </link>
  <!-- LEFT WHEEL1 -->
  <joint name="left_wheel_joint1" type="continuous">
    <parent link="base_link"/>
    <child link="left_wheel1"/>
    <origin rpy="-1.5707963267948966 0 0" xyz="-0.25 0.25 0.2"/>
    <axis xyz="0 0 1"/>
  </joint>
  <link name="left_wheel1">
    <visual>
      <geometry>
        <cylinder length="0.1" radius="0.2"/>
      </geometry>
      <material name="red"/>
    </visual>
    <collision>
      <geometry>
        <cylinder length="0.1" radius="0.2"/>
      </geometry>
    </collision>
    <inertial>
      <origin rpy="0 0 0" xyz="0 0 0"/>
      <mass value="0.1"/>
      <inertia ixx="0.0010833333333333335" ixy="0.0" ixz="0.0" iyy="0.0010833333333333335" iyz="0.0" izz="0.0020000000000000005"/>
    </inertial>
  </link>
  <!-- RIGHT WHEEL1 -->
  <joint name="right_wheel_joint1" type="continuous">
    <parent link="base_link"/>
    <child link="right_wheel1"/>
    <origin rpy="1.5707963267948966 0 0" xyz="-0.25 -0.25 0.2"/>
    <axis xyz="0 0 -1"/>
  </joint>
  <link name="right_wheel1">
    <visual>
      <geometry>
        <cylinder length="0.1" radius="0.2"/>
      </geometry>
      <material name="red"/>
    </visual>
    <collision>
      <geometry>
        <cylinder length="0.1" radius="0.2"/>
      </geometry>
    </collision>
    <inertial>
      <origin rpy="0 0 0" xyz="0 0 0"/>
      <mass value="0.1"/>
      <inertia ixx="0.0010833333333333335" ixy="0.0" ixz="0.0" iyy="0.0010833333333333335" iyz="0.0" izz="0.0020000000000000005"/>
    </inertial>
  </link>
  <joint name="robo_hub_joint" type="fixed">
    <parent link="base_link"/>
    <child link="robo_hub"/>
    <origin xyz="0 0 0"/>
  </joint>
  <link name="robo_hub">
    <visual>
      <origin xyz="0.1 0 0.4"/>
      <geometry>
        <box size="0.3 0.4 0.2"/>
      </geometry>
      <material name="green"/>
    </visual>
    <collision>
      <origin rpy="0 0 0" xyz="0.1 0 0.4"/>
      <geometry>
        <box size="0.3 0.4 0.2"/>
      </geometry>
    </collision>
    <inertial>
      <origin rpy="0 0 0" xyz="0.1 0 0.4"/>
      <mass value="0.5"/>
      <inertia ixx="0.008333333333333335" ixy="0.0" ixz="0.0" iyy="0.005416666666666667" iyz="0.0" izz="0.010416666666666666"/>
    </inertial>
  </link>
  <joint name="camera_joint" type="fixed">
    <parent link="chassis"/>
    <child link="camera_link"/>
    <origin rpy="0 0 0" xyz="0.305 0 0.08"/>
  </joint>
  <link name="camera_link">
    <visual>
      <geometry>
        <box size="0.010 0.03 0.03"/>
      </geometry>
      <material name="red"/>
    </visual>
  </link>
  <joint name="camera_optical_joint" type="fixed">
    <parent link="camera_link"/>
    <child link="camera_link_optical"/>
    <origin rpy="-1.5707963267948966 0 -1.5707963267948966" xyz="0 0 0"/>
  </joint>
  <link name="camera_link_optical"/>
  <gazebo reference="camera_link">
    <sensor name="camera" type="camera">
      <camera>
        <horizontal_fov>1.089</horizontal_fov>
        <image>
          <format>R8G8B8</format>
          <width>640</width>
          <height>480</height>
        </image>
        <clip>
          <near>0.05</near>
          <far>8.0</far>
        </clip>
      </camera>
      <always_on>1</always_on>
      <update_rate>30</update_rate>
      <visualize>true</visualize>
      <topic>camera/image_raw</topic>
    </sensor>
  </gazebo>
</robot>
