<sdf version='1.9'>
  <model name='robot'>
    <link name='base_link'>
      <inertial>
        <pose>0.05 0 0.3 0 0 0</pose>
        <mass>1</mass>
        <inertia>
          <ixx>0.026666666666666661</ixx>
          <ixy>0</ixy>
          <ixz>-0.005000000000000001</ixz>
          <iyy>0.061249999999999999</iyy>
          <iyz>0</iyz>
          <izz>0.061249999999999999</izz>
        </inertia>
      </inertial>
      <collision name='base_link_fixed_joint_lump__chassis_collision'>
        <pose>0 0 0.2 0 0 0</pose>
        <geometry>
          <box>
            <size>1 0.4 0.2</size>
          </box>
        </geometry>
      </collision>
      <collision name='base_link_fixed_joint_lump__robo_hub_collision_1'>
        <pose>0.1 0 0.4 0 0 0</pose>
        <geometry>
          <box>
            <size>0.3 0.4 0.2</size>
          </box>
        </geometry>
      </collision>
      <visual name='base_link_fixed_joint_lump__chassis_visual'>
        <pose>0 0 0.2 0 0 0</pose>
        <geometry>
          <box>
            <size>1 0.4 0.2</size>
          </box>
        </geometry>
        <material>
          <diffuse>0 0 1 1</diffuse>
          <ambient>0 0 1 1</ambient>
        </material>
      </visual>
      <visual name='base_link_fixed_joint_lump__camera_link_visual_1'>
        <pose>0.305 0 0.08 0 0 0</pose>
        <geometry>
          <box>
            <size>0.01 0.03 0.03</size>
          </box>
        </geometry>
        <material>
          <diffuse>1 0 0 1</diffuse>
          <ambient>1 0 0 1</ambient>
        </material>
      </visual>
      <visual name='base_link_fixed_joint_lump__robo_hub_visual_2'>
        <pose>0.1 0 0.4 0 0 0</pose>
        <geometry>
          <box>
            <size>0.3 0.4 0.2</size>
          </box>
        </geometry>
        <material>
          <diffuse>0 1 0 1</diffuse>
          <ambient>0 1 0 1</ambient>
        </material>
      </visual>
      <sensor name='camera' type='camera'>
        <camera>
          <horizontal_fov>1.089</horizontal_fov>
          <image>
            <format>R8G8B8</format>
            <width>640</width>
            <height>480</height>
          </image>
          <clip>
            <near>0.050000000000000003</near>
            <far>8</far>
          </clip>
        </camera>
        <always_on>true</always_on>
        <update_rate>30</update_rate>
        <visualize>true</visualize>
        <topic>camera/image_raw</topic>
        <pose>0.305 0 0.08 0 -0 0</pose>
      </sensor>
    </link>
    <joint name='left_wheel_joint' type='revolute'>
      <pose relative_to='base_link'>0.3 0.25 0.2 -1.570796326794896 0 0</pose>
      <parent>base_link</parent>
      <child>left_wheel</child>
      <axis>
        <xyz>0 0 1</xyz>
        <limit>
          <lower>-10000000000000000</lower>
          <upper>10000000000000000</upper>
        </limit>
        <dynamics>
          <spring_reference>0</spring_reference>
          <spring_stiffness>0</spring_stiffness>
        </dynamics>
      </axis>
    </joint>
    <link name='left_wheel'>
      <pose relative_to='left_wheel_joint'>0 0 0 0 0 0</pose>
      <inertial>
        <pose>0 0 0 0 0 0</pose>
        <mass>0.10000000000000001</mass>
        <inertia>
          <ixx>0.0010833333333333339</ixx>
          <ixy>0</ixy>
          <ixz>0</ixz>
          <iyy>0.0010833333333333339</iyy>
          <iyz>0</iyz>
          <izz>0.002</izz>
        </inertia>
      </inertial>
      <collision name='left_wheel_collision'>
        <pose>0 0 0 0 0 0</pose>
        <geometry>
          <cylinder>
            <length>0.10000000000000001</length>
            <radius>0.20000000000000001</radius>
          </cylinder>
        </geometry>
      </collision>
      <visual name='left_wheel_visual'>
        <pose>0 0 0 0 0 0</pose>
        <geometry>
          <cylinder>
            <length>0.10000000000000001</length>
            <radius>0.20000000000000001</radius>
          </cylinder>
        </geometry>
        <material>
          <diffuse>1 0 0 1</diffuse>
          <ambient>1 0 0 1</ambient>
        </material>
      </visual>
    </link>
    <joint name='left_wheel_joint1' type='revolute'>
      <pose relative_to='base_link'>-0.25 0.25 0.2 -1.570796326794896 0 0</pose>
      <parent>base_link</parent>
      <child>left_wheel1</child>
      <axis>
        <xyz>0 0 1</xyz>
        <limit>
          <lower>-10000000000000000</lower>
          <upper>10000000000000000</upper>
        </limit>
        <dynamics>
          <spring_reference>0</spring_reference>
          <spring_stiffness>0</spring_stiffness>
        </dynamics>
      </axis>
    </joint>
    <link name='left_wheel1'>
      <pose relative_to='left_wheel_joint1'>0 0 0 0 0 0</pose>
      <inertial>
        <pose>0 0 0 0 0 0</pose>
        <mass>0.10000000000000001</mass>
        <inertia>
          <ixx>0.0010833333333333339</ixx>
          <ixy>0</ixy>
          <ixz>0</ixz>
          <iyy>0.0010833333333333339</iyy>
          <iyz>0</iyz>
          <izz>0.002</izz>
        </inertia>
      </inertial>
      <collision name='left_wheel1_collision'>
        <pose>0 0 0 0 0 0</pose>
        <geometry>
          <cylinder>
            <length>0.10000000000000001</length>
            <radius>0.20000000000000001</radius>
          </cylinder>
        </geometry>
      </collision>
      <visual name='left_wheel1_visual'>
        <pose>0 0 0 0 0 0</pose>
        <geometry>
          <cylinder>
            <length>0.10000000000000001</length>
            <radius>0.20000000000000001</radius>
          </cylinder>
        </geometry>
        <material>
          <diffuse>1 0 0 1</diffuse>
          <ambient>1 0 0 1</ambient>
        </material>
      </visual>
    </link>
    <joint name='right_wheel_joint' type='revolute'>
      <pose relative_to='base_link'>0.3 -0.25 0.2 1.570796326794896 0 0</pose>
      <parent>base_link</parent>
      <child>right_wheel</child>
      <axis>
        <xyz>0 0 -1</xyz>
        <limit>
          <lower>-10000000000000000</lower>
          <upper>10000000000000000</upper>
        </limit>
        <dynamics>
          <spring_reference>0</spring_reference>
          <spring_stiffness>0</spring_stiffness>
        </dynamics>
      </axis>
    </joint>
    <link name='right_wheel'>
      <pose relative_to='right_wheel_joint'>0 0 0 0 0 0</pose>
      <inertial>
        <pose>0 0 0 0 0 0</pose>
        <mass>0.10000000000000001</mass>
        <inertia>
          <ixx>0.0010833333333333339</ixx>
          <ixy>0</ixy>
          <ixz>0</ixz>
          <iyy>0.0010833333333333339</iyy>
          <iyz>0</iyz>
          <izz>0.002</izz>
        </inertia>
      </inertial>
      <collision name='right_wheel_collision'>
        <pose>0 0 0 0 0 0</pose>
        <geometry>
          <cylinder>
            <length>0.10000000000000001</length>
            <radius>0.20000000000000001</radius>
          </cylinder>
        </geometry>
      </collision>
      <visual name='right_wheel_visual'>
        <pose>0 0 0 0 0 0</pose>
        <geometry>
          <cylinder>
            <length>0.10000000000000001</length>
            <radius>0.20000000000000001</radius>
          </cylinder>
        </geometry>
        <material>
          <diffuse>1 0 0 1</diffuse>
          <ambient>1 0 0 1</ambient>
        </material>
      </visual>
    </link>
    <joint name='right_wheel_joint1' type='revolute'>
      <pose relative_to='base_link'>-0.25 -0.25 0.2 1.570796326794896 0 0</pose>
      <parent>base_link</parent>
      <child>right_wheel1</child>
      <axis>
        <xyz>0 0 -1</xyz>
        <limit>
          <lower>-10000000000000000</lower>
          <upper>10000000000000000</upper>
        </limit>
        <dynamics>
          <spring_reference>0</spring_reference>
          <spring_stiffness>0</spring_stiffness>
        </dynamics>
      </axis>
    </joint>
    <link name='right_wheel1'>
      <pose relative_to='right_wheel_joint1'>0 0 0 0 0 0</pose>
      <inertial>
        <pose>0 0 0 0 0 0</pose>
        <mass>0.10000000000000001</mass>
        <inertia>
          <ixx>0.0010833333333333339</ixx>
          <ixy>0</ixy>
          <ixz>0</ixz>
          <iyy>0.0010833333333333339</iyy>
          <iyz>0</iyz>
          <izz>0.002</izz>
        </inertia>
      </inertial>
      <collision name='right_wheel1_collision'>
        <pose>0 0 0 0 0 0</pose>
        <geometry>
          <cylinder>
            <length>0.10000000000000001</length>
            <radius>0.20000000000000001</radius>
          </cylinder>
        </geometry>
      </collision>
      <visual name='right_wheel1_visual'>
        <pose>0 0 0 0 0 0</pose>
        <geometry>
          <cylinder>
            <length>0.10000000000000001</length>
            <radius>0.20000000000000001</radius>
          </cylinder>
        </geometry>
        <material>
          <diffuse>1 0 0 1</diffuse>
          <ambient>1 0 0 1</ambient>
        </material>
      </visual>
    </link>
    <pose>0 0 0.05 0 0 0</pose>
    <plugin name='ignition::gazebo::systems::DiffDrive' filename='libignition-gazebo-diff-drive-system.so'>
      <left_joint>left_wheel_joint</left_joint>
      <right_joint>right_wheel_joint</right_joint>
      <wheel_separation>0.3</wheel_separation>
      <wheel_radius>0.05</wheel_radius>
      <odom_publish_frequency>1</odom_publish_frequency>
      <topic>cmd_vel</topic>
    </plugin>
    <plugin name='ignition::gazebo::systems::JointStatePublisher' filename='libignition-gazebo-joint-state-publisher-system'/>
    <plugin name='ignition::gazebo::systems::OdometryPublisher' filename='libignition-gazebo-odometry-publisher-system'>
      <odom_frame>world</odom_frame>
      <robot_base_frame>base_link</robot_base_frame>
    </plugin>
    <frame name='camera_optical_joint' attached_to='camera_link'>
      <pose>0 0 0 -1.5708 -0 -1.5708</pose>
    </frame>
    <frame name='camera_link_optical' attached_to='camera_optical_joint'/>
    <frame name='camera_joint' attached_to='chassis'>
      <pose>0.305 0 0.08 0 -0 0</pose>
    </frame>
    <frame name='camera_link' attached_to='camera_joint'/>
    <frame name='chassis_joint' attached_to='base_link'>
      <pose>0 0 0 0 -0 0</pose>
    </frame>
    <frame name='chassis' attached_to='chassis_joint'/>
    <frame name='robo_hub_joint' attached_to='base_link'>
      <pose>0 0 0 0 -0 0</pose>
    </frame>
    <frame name='robo_hub' attached_to='robo_hub_joint'/>
  </model>
</sdf>
