<?xml version="1.0" ?>
<!-- =================================================================================== -->
<!-- |    This document was autogenerated by xacro from robot.urdf.xacro               | -->
<!-- |    EDITING THIS FILE BY HAND IS NOT RECOMMENDED                                 | -->
<!-- =================================================================================== -->
<robot name="robot">
  <material name="black">
    <color rgba="0 0 0 1"/>
  </material>
  <material name="white">
    <color rgba="1 1 1 1"/>
  </material>
  <material name="red">
    <color rgba="1 0 0 1"/>
  </material>
  <material name="green">
    <color rgba="0 1 0 1"/>
  </material>
  <material name="blue">
    <color rgba="0 0 1 1"/>
  </material>
  <material name="yellow">
    <color rgba="1 1 0 1"/>
  </material>
  <material name="magenta">
    <color rgba="1 0 1 1"/>
  </material>
  <material name="cyan">
    <color rgba="0 1 1 1"/>
  </material>
  <gazebo>
    <pose>0 0 0.05 0 0 3.141592653589793</pose>
    <plugin filename="libignition-gazebo-diff-drive-system.so" name="ignition::gazebo::systems::DiffDrive">
      <left_joint>left_wheel_joint</left_joint>
      <right_joint>right_wheel_joint</right_joint>
      <wheel_separation>0.3</wheel_separation>
      <wheel_radius>0.05</wheel_radius>
      <odom_publish_frequency>1</odom_publish_frequency>
      <topic>cmd_vel</topic>
    </plugin>
    <plugin filename="libignition-gazebo-joint-state-publisher-system" name="ignition::gazebo::systems::JointStatePublisher">
        </plugin>
    <plugin filename="libignition-gazebo-odometry-publisher-system" name="ignition::gazebo::systems::OdometryPublisher">
      <odom_frame>world</odom_frame>
      <robot_base_frame>base_link</robot_base_frame>
    </plugin>
  </gazebo>
  <gazebo reference="caster_wheel">
    <mu1 value="0.0"/>
    <mu2 value="0.0"/>
  </gazebo>
  <link name="base_link">
    </link>
  <joint name="north_wall_joint" type="fixed">
    <parent link="base_link"/>
    <child link="north_wall"/>
    <origin xyz="0 5.0 1.0"/>
  </joint>
  <link name="north_wall">
    <visual>
      <origin rpy="0 0 0" xyz="0 0 0"/>
      <geometry>
        <box size="10 0.1 2"/>
      </geometry>
      <material name="blue"/>
    </visual>
    <collision>
      <origin rpy="0 0 0" xyz="0 0 0"/>
      <geometry>
        <box size="10 0.1 2"/>
      </geometry>
    </collision>
    <inertial>
      <origin rpy="0 0 0" xyz="0 0 0"/>
      <mass value="0.5"/>
      <inertia ixx="0.1670833333333333" ixy="0.0" ixz="0.0" iyy="4.333333333333333" iyz="0.0" izz="4.167083333333333"/>
    </inertial>
  </link>
  <joint name="south_wall_joint" type="fixed">
    <parent link="base_link"/>
    <child link="south_wall"/>
    <origin xyz="0 -5.0 1.0"/>
  </joint>
  <link name="south_wall">
    <visual>
      <origin rpy="0 0 0" xyz="0 0 0"/>
      <geometry>
        <box size="10 0.1 2"/>
      </geometry>
      <material name="red"/>
    </visual>
    <collision>
      <origin rpy="0 0 0" xyz="0 0 0"/>
      <geometry>
        <box size="10 0.1 2"/>
      </geometry>
    </collision>
    <inertial>
      <origin rpy="0 0 0" xyz="0 0 0"/>
      <mass value="0.5"/>
      <inertia ixx="0.1670833333333333" ixy="0.0" ixz="0.0" iyy="4.333333333333333" iyz="0.0" izz="4.167083333333333"/>
    </inertial>
  </link>
  <joint name="east_wall_joint" type="fixed">
    <parent link="base_link"/>
    <child link="east_wall"/>
    <origin xyz="5.0 0 1.0"/>
  </joint>
  <link name="east_wall">
    <visual>
      <origin rpy="0 0 1.5707963267948966" xyz="0 0 0"/>
      <geometry>
        <box size="10 0.1 2"/>
      </geometry>
      <material name="magenta"/>
    </visual>
    <collision>
      <origin rpy="0 0 1.5707963267948966" xyz="0 0 0"/>
      <geometry>
        <box size="10 0.1 2"/>
      </geometry>
    </collision>
    <inertial>
      <origin rpy="0 0 1.5707963267948966" xyz="0 0 0"/>
      <mass value="0.5"/>
      <inertia ixx="0.1670833333333333" ixy="0.0" ixz="0.0" iyy="4.333333333333333" iyz="0.0" izz="4.167083333333333"/>
    </inertial>
  </link>
  <joint name="west_wall_joint_n" type="fixed">
    <parent link="base_link"/>
    <child link="west_wall_n"/>
    <origin rpy="0 0 1.5707963267948966" xyz="-5.0 2.5 1.0"/>
  </joint>
  <link name="west_wall_n">
    <visual>
      <origin xyz="0 0 0"/>
      <geometry>
        <box size="4.0 0.1 2"/>
      </geometry>
      <material name="red"/>
    </visual>
    <collision>
      <origin xyz="0 0 0"/>
      <geometry>
        <box size="4.0 0.1 2"/>
      </geometry>
    </collision>
    <inertial>
      <origin xyz="0 0 0"/>
      <mass value="0.5"/>
      <inertia ixx="0.1670833333333333" ixy="0.0" ixz="0.0" iyy="1.2083333333333333" iyz="0.0" izz="1.0420833333333333"/>
    </inertial>
  </link>
  <joint name="west_wall_joint_s" type="fixed">
    <parent link="base_link"/>
    <child link="west_wall_s"/>
    <origin rpy="0 0 1.5707963267948966" xyz="-5.0 -2.5 1.0"/>
  </joint>
  <link name="west_wall_s">
    <visual>
      <origin xyz="0 0 0"/>
      <geometry>
        <box size="4.0 0.1 2"/>
      </geometry>
      <material name="red"/>
    </visual>
    <collision>
      <origin xyz="0 0 0"/>
      <geometry>
        <box size="4.0 0.1 2"/>
      </geometry>
    </collision>
    <inertial>
      <origin xyz="0 0 0"/>
      <mass value="0.5"/>
      <inertia ixx="0.1670833333333333" ixy="0.0" ixz="0.0" iyy="1.2083333333333333" iyz="0.0" izz="1.0420833333333333"/>
    </inertial>
  </link>
  <joint name="west_wall_joint_u" type="fixed">
    <parent link="base_link"/>
    <child link="west_wall_u"/>
    <origin rpy="0 0 1.5707963267948966" xyz="-5.0 0 1.75"/>
  </joint>
  <link name="west_wall_u">
    <visual>
      <origin xyz="0 0 0"/>
      <geometry>
        <box size="2 0.1 0.5"/>
      </geometry>
      <material name="red"/>
    </visual>
    <collision>
      <origin xyz="0 0 0"/>
      <geometry>
        <box size="2 0.1 0.5"/>
      </geometry>
    </collision>
    <inertial>
      <origin xyz="0 0 0"/>
      <mass value="0.5"/>
      <inertia ixx="0.010833333333333334" ixy="0.0" ixz="0.0" iyy="0.17708333333333331" iyz="0.0" izz="0.1670833333333333"/>
    </inertial>
  </link>
  <joint name="ne_tower_joint" type="fixed">
    <parent link="base_link"/>
    <child link="ne_tower"/>
    <origin xyz="5.0 5.0 2.0"/>
  </joint>
  <link name="ne_tower">
    <visual>
      <origin rpy="0 0 1.5707963267948966" xyz="0 0 0"/>
      <geometry>
        <cylinder length="4" radius="1"/>
      </geometry>
      <material name="blue"/>
    </visual>
    <collision>
      <origin rpy="0 0 1.5707963267948966" xyz="0 0 0"/>
      <geometry>
        <cylinder length="4" radius="1"/>
      </geometry>
    </collision>
    <inertial>
      <origin rpy="0 0 0" xyz="0 0 0"/>
      <mass value="0.1"/>
      <inertia ixx="0.15833333333333333" ixy="0.0" ixz="0.0" iyy="0.15833333333333333" iyz="0.0" izz="0.05"/>
    </inertial>
  </link>
  <joint name="se_tower_joint" type="fixed">
    <parent link="base_link"/>
    <child link="se_tower"/>
    <origin xyz="5.0 -5.0 2.0"/>
  </joint>
  <link name="se_tower">
    <visual>
      <origin rpy="0 0 1.5707963267948966" xyz="0 0 0"/>
      <geometry>
        <cylinder length="4" radius="1"/>
      </geometry>
      <material name="red"/>
    </visual>
    <collision>
      <origin rpy="0 0 1.5707963267948966" xyz="0 0 0"/>
      <geometry>
        <cylinder length="4" radius="1"/>
      </geometry>
    </collision>
    <inertial>
      <origin rpy="0 0 0" xyz="0 0 0"/>
      <mass value="0.1"/>
      <inertia ixx="0.15833333333333333" ixy="0.0" ixz="0.0" iyy="0.15833333333333333" iyz="0.0" izz="0.05"/>
    </inertial>
  </link>
  <joint name="sw_tower_joint" type="fixed">
    <parent link="base_link"/>
    <child link="sw_tower"/>
    <origin xyz="-5.0 -5.0 2.0"/>
  </joint>
  <link name="sw_tower">
    <visual>
      <origin rpy="0 0 1.5707963267948966" xyz="0 0 0"/>
      <geometry>
        <cylinder length="4" radius="1"/>
      </geometry>
      <material name="red"/>
    </visual>
    <collision>
      <origin rpy="0 0 1.5707963267948966" xyz="0 0 0"/>
      <geometry>
        <cylinder length="4" radius="1"/>
      </geometry>
    </collision>
    <inertial>
      <origin rpy="0 0 0" xyz="0 0 0"/>
      <mass value="0.1"/>
      <inertia ixx="0.15833333333333333" ixy="0.0" ixz="0.0" iyy="0.15833333333333333" iyz="0.0" izz="0.05"/>
    </inertial>
  </link>
  <joint name="nw_tower_joint" type="fixed">
    <parent link="base_link"/>
    <child link="nw_tower"/>
    <origin xyz="-5.0 5.0 2.0"/>
  </joint>
  <link name="nw_tower">
    <visual>
      <origin rpy="0 0 1.5707963267948966" xyz="0 0 0"/>
      <geometry>
        <cylinder length="4" radius="1"/>
      </geometry>
      <material name="red"/>
    </visual>
    <collision>
      <origin rpy="0 0 1.5707963267948966" xyz="0 0 0"/>
      <geometry>
        <cylinder length="4" radius="1"/>
      </geometry>
    </collision>
    <inertial>
      <origin rpy="0 0 0" xyz="0 0 0"/>
      <mass value="0.1"/>
      <inertia ixx="0.15833333333333333" ixy="0.0" ixz="0.0" iyy="0.15833333333333333" iyz="0.0" izz="0.05"/>
    </inertial>
  </link>
  <joint name="chassis_joint" type="fixed">
    <parent link="base_link"/>
    <child link="chassis"/>
    <origin xyz="-0.1 0 0"/>
  </joint>
  <link name="chassis">
    <visual>
      <origin rpy="0 0 0" xyz="0.15 0 0.075"/>
      <geometry>
        <box size="0.3 0.3 0.15"/>
      </geometry>
      <material name="green"/>
    </visual>
    <collision>
      <origin rpy="0 0 0" xyz="0.15 0 0.075"/>
      <geometry>
        <box size="0.3 0.3 0.15"/>
      </geometry>
    </collision>
    <inertial>
      <origin rpy="0 0 0" xyz="0.15 0 0.075"/>
      <mass value="0.5"/>
      <inertia ixx="0.004687499999999999" ixy="0.0" ixz="0.0" iyy="0.004687499999999999" iyz="0.0" izz="0.0075"/>
    </inertial>
  </link>
  <!-- LEFT WHEEL -->
  <joint name="left_wheel_joint" type="continuous">
    <parent link="base_link"/>
    <child link="left_wheel"/>
    <origin rpy="-1.5707963267948966 0 0" xyz="0 0.175 0"/>
    <axis xyz="0 0 1"/>
  </joint>
  <link name="left_wheel">
    <visual>
      <geometry>
        <cylinder length="0.04" radius="0.05"/>
      </geometry>
      <material name="blue"/>
    </visual>
    <collision>
      <geometry>
        <cylinder length="0.04" radius="0.05"/>
      </geometry>
    </collision>
    <inertial>
      <origin rpy="0 0 0" xyz="0 0 0"/>
      <mass value="0.1"/>
      <inertia ixx="7.583333333333335e-05" ixy="0.0" ixz="0.0" iyy="7.583333333333335e-05" iyz="0.0" izz="0.00012500000000000003"/>
    </inertial>
  </link>
  <!-- RIGHT WHEEL -->
  <joint name="right_wheel_joint" type="continuous">
    <parent link="base_link"/>
    <child link="right_wheel"/>
    <origin rpy="1.5707963267948966 0 0" xyz="0 -0.175 0"/>
    <axis xyz="0 0 -1"/>
  </joint>
  <link name="right_wheel">
    <visual>
      <geometry>
        <cylinder length="0.04" radius="0.05"/>
      </geometry>
      <material name="blue"/>
    </visual>
    <collision>
      <geometry>
        <cylinder length="0.04" radius="0.05"/>
      </geometry>
    </collision>
    <inertial>
      <origin rpy="0 0 0" xyz="0 0 0"/>
      <mass value="0.1"/>
      <inertia ixx="7.583333333333335e-05" ixy="0.0" ixz="0.0" iyy="7.583333333333335e-05" iyz="0.0" izz="0.00012500000000000003"/>
    </inertial>
  </link>
  <!-- CASTER WHEEL -->
  <joint name="caster_wheel_joint" type="fixed">
    <parent link="chassis"/>
    <child link="caster_wheel"/>
    <origin rpy="0 0 0" xyz="0.24 0 0"/>
  </joint>
  <link name="caster_wheel">
    <visual>
      <geometry>
        <sphere radius="0.05"/>
      </geometry>
      <material name="blue"/>
    </visual>
    <collision>
      <geometry>
        <sphere radius="0.05"/>
      </geometry>
    </collision>
    <inertial>
      <origin rpy="0 0 0" xyz="0 0 0"/>
      <mass value="1.0"/>
      <inertia ixx="0.0010000000000000002" ixy="0.0" ixz="0.0" iyy="0.0010000000000000002" iyz="0.0" izz="0.0010000000000000002"/>
    </inertial>
  </link>
</robot>
